<?xml version="1.0" ?>
<!-- =================================================================================== -->
<!-- |    This document was autogenerated by xacro from /home/rashid/ros_ws/src/bot_resources/urdf/bot_arm.xacro | -->
<!-- |    EDITING THIS FILE BY HAND IS NOT RECOMMENDED                                 | -->
<!-- =================================================================================== -->
<!--
This is a very simple 3 DOF robot arm.
Three  movements are:
1. revolve around z axis (-90 to +90 degrees)
2. Upper arm and lower arm joints(0 to 90 degrees)
Each link has been colored differently to understand its movement.
-->
<robot name="first_arm">
    <material name="red">
        <color rgba="1 0 0 1" />
    </material>
    <material name="green">
        <color rgba="0 1 0 1" />
    </material>
    <material name="yellow">
        <color rgba="0 1 1 1" />
    </material>
    <material name="white">
        <color rgba="1 1 1 0.5" />
    </material>
    <material name="blue">
        <color rgba="0 0 1 1" />
    </material>
    <link name="base_link" />
    <link name="base_bot">
        <visual>
            <geometry>
                <cylinder length="0.2" radius="0.3" />
            </geometry>
            <origin xyz="0 0 0.1" />
            <material name="white" />
        </visual>
        <collision>
            <geometry>
                <cylinder length="0.2" radius="0.3" />
            </geometry>
            <origin xyz="0 0 0.1" />
        </collision>
        <inertial>
            <mass value="0.1" />
            <origin xyz="0 0 0" rpy="0 0 0" />
            <inertia ixx="0.03" iyy="0.03" izz="0.03" ixy="0.0" ixz="0.0" iyz="0.0" />
        </inertial>
    </link>
    <joint name="base_to_base_bot" type="fixed">
        <parent link="base_link" />
        <child link="base_bot" />
        <origin xyz="0 0 0" />
    </joint>
    <link name="base_yaw">
        <visual>
            <geometry>
                <cylinder length="0.2" radius="0.1" />
            </geometry>
            <origin xyz="0 0 0.1" />
            <material name="red" />
        </visual>
        <collision>
            <geometry>
                <cylinder length="0.2" radius="0.1" />
            </geometry>
            <origin xyz="0 0 0.1" />
        </collision>
        <inertial>
            <mass value="0.1" />
            <origin xyz="0 0 0" rpy="0 0 0" />
            <inertia ixx="0.03" iyy="0.03" izz="0.03" ixy="0.0" ixz="0.0" iyz="0.0" />
        </inertial>
    </link>
    <joint name="joint_0" type="revolute">
        <parent link="base_bot" />
        <child link="base_yaw" />
        <origin xyz="0 0 0.2" />
        <limit effort="0.0" lower="-1.57" upper="1.57" velocity="1.0" />
        <axis xyz="0 0 1" />
    </joint>
    <link name="upper_arm">
        <visual>
            <geometry>
                <cylinder length="0.6" radius="0.1" />
            </geometry>
            <origin rpy="0 0 0" xyz="0.1 0 0.3" />
            <material name="yellow" />
        </visual>
        <collision>
            <geometry>
                <cylinder length="0.6" radius="0.1" />
            </geometry>
            <origin rpy="0 0 0" xyz="0.1 0 0.3" />
        </collision>
        <inertial>
            <mass value="0.1" />
            <origin xyz="0 0 0" rpy="0 0 0" />
            <inertia ixx="0.03" iyy="0.03" izz="0.03" ixy="0.0" ixz="0.0" iyz="0.0" />
        </inertial>
    </link>
    <joint name="joint_1" type="revolute">
        <parent link="base_yaw" />
        <child link="upper_arm" />
        <origin xyz="0.1 0 0.2" />
        <limit effort="0.0" lower="0" upper="1.57" velocity="2.0" />
        <axis xyz="1 0 0" />
    </joint>
    <link name="arm">
        <visual>
            <geometry>
                <cylinder length="0.6" radius="0.1" />
            </geometry>
            <origin rpy="0 0 0" xyz="0 0 0.3" />
            <material name="blue" />
        </visual>
        <collision>
            <geometry>
                <cylinder length="0.6" radius="0.1" />
            </geometry>
            <origin rpy="0 0 0" xyz="0 0 0.3" />
        </collision>
        <inertial>
            <mass value="0.1" />
            <origin xyz="0 0 0" rpy="0 0 0" />
            <inertia ixx="0.03" iyy="0.03" izz="0.03" ixy="0.0" ixz="0.0" iyz="0.0" />
        </inertial>
    </link>
    <joint name="joint_2" type="revolute">
        <parent link="upper_arm" />
        <child link="arm" />
        <origin xyz="-0.1 0 0.6" />
        <limit effort="0.0" lower="0" upper="1.57" velocity="2.0" />
        <axis xyz="1 0 0" />
    </joint>
    <link name="finger_low">
        <visual>
            <geometry>
                <cylinder length="0.1" radius="0.02" />
            </geometry>
            <origin rpy="0 0 0" xyz="0 0 0.02" />
            <material name="yellow" />
        </visual>
        <collision>
            <geometry>
                <cylinder length="0.1" radius="0.02" />
            </geometry>
            <origin rpy="0 0 0" xyz="0 0 0.6" />
        </collision>
        <inertial>
            <mass value="0.1" />
            <origin xyz="0 0 0" rpy="0 0 0" />
            <inertia ixx="0.03" iyy="0.03" izz="0.03" ixy="0.0" ixz="0.0" iyz="0.0" />
        </inertial>
    </link>
    <joint name="joint_fixed_finger" type="fixed">
        <parent link="arm" />
        <child link="finger_low" />
        <origin xyz="0 0 0.6" />
    </joint>
    <transmission name="trans_joint_0">
        <type>transmission_interface/SimpleTransmission</type>
        <joint name="joint_0">
            <hardwareInterface>hardware_interface/EffortJointInterface</hardwareInterface>
        </joint>
        <actuator name="joint_0_motor">
            <hardwareInterface>hardware_interface/EffortJointInterface</hardwareInterface>
            <mechanicalReduction>1</mechanicalReduction>
        </actuator>
    </transmission>
    <transmission name="trans_joint_1">
        <type>transmission_interface/SimpleTransmission</type>
        <joint name="joint_1">
            <hardwareInterface>hardware_interface/EffortJointInterface</hardwareInterface>
        </joint>
        <actuator name="joint_1_motor">
            <hardwareInterface>hardware_interface/EffortJointInterface</hardwareInterface>
            <mechanicalReduction>1</mechanicalReduction>
        </actuator>
    </transmission>
    <transmission name="trans_joint_2">
        <type>transmission_interface/SimpleTransmission</type>
        <joint name="joint_2">
            <hardwareInterface>hardware_interface/EffortJointInterface</hardwareInterface>
        </joint>
        <actuator name="joint_2_motor">
            <hardwareInterface>hardware_interface/EffortJointInterface</hardwareInterface>
            <mechanicalReduction>1</mechanicalReduction>
        </actuator>
    </transmission>
    <gazebo>
        <plugin name="gazebo_ros_control">
            <robotNamespace>/</robotNamespace>
        </plugin>
    </gazebo>
</robot>
